{
 "cells": [
  {
   "cell_type": "code",
   "execution_count": null,
   "id": "342edf21",
   "metadata": {},
   "outputs": [],
   "source": [
    "!pip install fosforml"
   ]
  },
  {
   "cell_type": "code",
   "execution_count": 1,
   "id": "85d89ea6",
   "metadata": {},
   "outputs": [],
   "source": [
    "import fosforml"
   ]
  },
  {
   "cell_type": "code",
   "execution_count": 2,
   "id": "947a3773",
   "metadata": {},
   "outputs": [],
   "source": [
    "from fosforml.model_manager.snowflakesession import get_session, get_connection_params\n",
    "\n",
    "session = get_session()\n",
    "connection_params = get_connection_params()"
   ]
  },
  {
   "cell_type": "code",
   "execution_count": 3,
   "id": "7512dbb9",
   "metadata": {},
   "outputs": [],
   "source": [
    "import getpass"
   ]
  },
  {
   "cell_type": "code",
   "execution_count": 4,
   "id": "b5f0c7db",
   "metadata": {
    "scrolled": true
   },
   "outputs": [
    {
     "name": "stdin",
     "output_type": "stream",
     "text": [
      " ········\n"
     ]
    }
   ],
   "source": [
    "password = getpass.getpass()"
   ]
  },
  {
   "cell_type": "code",
   "execution_count": 8,
   "id": "5e5a3858",
   "metadata": {},
   "outputs": [
    {
     "name": "stdout",
     "output_type": "stream",
     "text": [
      "Error while creating snowflake session 250001 (08001): Failed to connect to DB: fya62509.us-east-1.snowflakecomputing.com:443. Error connecting to Snowflake via Snowpark Container Services. Please use OAuth when connecting to Snowflake. For more information please refer to https://docs.snowflake.com/en/developer-guide/snowpark-container-services/additional-considerations-services-jobs#connecting-to-snowflake-from-inside-a-container.\n"
     ]
    }
   ],
   "source": [
    "from snowflake.snowpark.session import Session\n",
    "\n",
    "def get_session():\n",
    "    \"\"\"\n",
    "    Method creates snowflake session object.\n",
    "    :return:\n",
    "    \"\"\"\n",
    "    try:\n",
    "        CONNECTION_PARAMETERS = {\n",
    "            \"account\": 'fya62509.us-east-1',\n",
    "            \"user\": 'RAVIKUMARHALIGODE',\n",
    "            \"password\": password,\n",
    "            \"role\": 'RAVIKUMARHALIGODE',\n",
    "            \"database\": 'RAVI_TESTING',\n",
    "            \"warehouse\": 'FOSFOR_INSIGHT_WH',\n",
    "            \"schema\": 'RAVI_TESTING'\n",
    "        }\n",
    "        return Session.builder.configs(CONNECTION_PARAMETERS).create()\n",
    "    except Exception as ex:\n",
    "        print(\"Error while creating snowflake session\", ex)\n",
    "        return ex\n",
    "\n",
    "session = get_session()\n",
    "# import pandas as pd\n",
    "# my_data = pd.read_csv('mlflow_sample_data 2.csv')\n",
    "# my_data.columns = map(lambda x: str(x).upper(), my_data.columns)\n",
    "# my_data.columns = my_data.columns.str.replace(' ', '_')\n",
    "# my_data = my_data.loc[:, ~my_data.columns.str.contains('^Unnamed')]\n",
    "# my_data.head()\n",
    "# session.write_pandas(my_data, table_name=\"mlflow_sample_data\", auto_create_table=True, overwrite=True)"
   ]
  },
  {
   "cell_type": "code",
   "execution_count": 9,
   "id": "3fa414ef-cd1a-4fec-bdf3-07abe9b70bcb",
   "metadata": {},
   "outputs": [],
   "source": [
    "SNOWFLAKE_ACCOUNT = \"fya62509\"\n",
    "SNOWFLAKE_HOST = \"fya62509.us-east-1.snowflakecomputing.com\""
   ]
  },
  {
   "cell_type": "code",
   "execution_count": 12,
   "id": "7e6d5611-dfa3-4d56-bca9-2a99a4178ecb",
   "metadata": {},
   "outputs": [
    {
     "ename": "NameError",
     "evalue": "name 'snowflake' is not defined",
     "output_type": "error",
     "traceback": [
      "\u001b[0;31m---------------------------------------------------------------------------\u001b[0m",
      "\u001b[0;31mNameError\u001b[0m                                 Traceback (most recent call last)",
      "Cell \u001b[0;32mIn[12], line 5\u001b[0m\n\u001b[1;32m      2\u001b[0m  \u001b[38;5;28;01mwith\u001b[39;00m \u001b[38;5;28mopen\u001b[39m(\u001b[38;5;124m'\u001b[39m\u001b[38;5;124m/snowflake/session/token\u001b[39m\u001b[38;5;124m'\u001b[39m, \u001b[38;5;124m'\u001b[39m\u001b[38;5;124mr\u001b[39m\u001b[38;5;124m'\u001b[39m) \u001b[38;5;28;01mas\u001b[39;00m f:\n\u001b[1;32m      3\u001b[0m      \u001b[38;5;28;01mreturn\u001b[39;00m f\u001b[38;5;241m.\u001b[39mread()\n\u001b[0;32m----> 5\u001b[0m conn \u001b[38;5;241m=\u001b[39m \u001b[43msnowflake\u001b[49m\u001b[38;5;241m.\u001b[39mconnector\u001b[38;5;241m.\u001b[39mconnect(\n\u001b[1;32m      6\u001b[0m   host \u001b[38;5;241m=\u001b[39m os\u001b[38;5;241m.\u001b[39mgetenv(\u001b[38;5;124m'\u001b[39m\u001b[38;5;124mSNOWFLAKE_HOST\u001b[39m\u001b[38;5;124m'\u001b[39m),\n\u001b[1;32m      7\u001b[0m   account \u001b[38;5;241m=\u001b[39m os\u001b[38;5;241m.\u001b[39mgetenv(\u001b[38;5;124m'\u001b[39m\u001b[38;5;124mSNOWFLAKE_ACCOUNT\u001b[39m\u001b[38;5;124m'\u001b[39m),\n\u001b[1;32m      8\u001b[0m   token \u001b[38;5;241m=\u001b[39m get_login_token(),\n\u001b[1;32m      9\u001b[0m   authenticator \u001b[38;5;241m=\u001b[39m \u001b[38;5;124m'\u001b[39m\u001b[38;5;124moauth\u001b[39m\u001b[38;5;124m'\u001b[39m\n\u001b[1;32m     10\u001b[0m )\n",
      "\u001b[0;31mNameError\u001b[0m: name 'snowflake' is not defined"
     ]
    }
   ],
   "source": [
    "def get_login_token():\n",
    " with open('/snowflake/session/token', 'r') as f:\n",
    "     return f.read()\n",
    "\n",
    "conn = snowflake.connector.connect(\n",
    "  host = os.getenv('SNOWFLAKE_HOST'),\n",
    "  account = os.getenv('SNOWFLAKE_ACCOUNT'),\n",
    "  token = get_login_token(),\n",
    "  authenticator = 'oauth'\n",
    ")"
   ]
  },
  {
   "cell_type": "code",
   "execution_count": 13,
   "id": "c6322804-a3df-4841-82b3-b0c21f6987a1",
   "metadata": {},
   "outputs": [
    {
     "ename": "NameError",
     "evalue": "name 'snowflake' is not defined",
     "output_type": "error",
     "traceback": [
      "\u001b[0;31m---------------------------------------------------------------------------\u001b[0m",
      "\u001b[0;31mNameError\u001b[0m                                 Traceback (most recent call last)",
      "Cell \u001b[0;32mIn[13], line 1\u001b[0m\n\u001b[0;32m----> 1\u001b[0m conn \u001b[38;5;241m=\u001b[39m \u001b[43msnowflake\u001b[49m\u001b[38;5;241m.\u001b[39mconnector\u001b[38;5;241m.\u001b[39mconnect(\n\u001b[1;32m      2\u001b[0m   account \u001b[38;5;241m=\u001b[39m os\u001b[38;5;241m.\u001b[39mgetenv(\u001b[38;5;124m'\u001b[39m\u001b[38;5;124mSNOWFLAKE_ACCOUNT\u001b[39m\u001b[38;5;124m'\u001b[39m),\n\u001b[1;32m      3\u001b[0m   user \u001b[38;5;241m=\u001b[39m \u001b[38;5;124m'\u001b[39m\u001b[38;5;124mRAVIKUMARHALIGODE\u001b[39m\u001b[38;5;124m'\u001b[39m,\n\u001b[1;32m      4\u001b[0m   password \u001b[38;5;241m=\u001b[39m \u001b[38;5;124m'\u001b[39m\u001b[38;5;124mKayakave@1983\u001b[39m\u001b[38;5;124m'\u001b[39m\n\u001b[1;32m      5\u001b[0m )\n",
      "\u001b[0;31mNameError\u001b[0m: name 'snowflake' is not defined"
     ]
    }
   ],
   "source": [
    "conn = snowflake.connector.connect(\n",
    "  account = os.getenv('SNOWFLAKE_ACCOUNT'),\n",
    "  user = 'RAVIKUMARHALIGODE',\n",
    "  password = 'Kayakave@1983'\n",
    ")"
   ]
  },
  {
   "cell_type": "code",
   "execution_count": null,
   "id": "ae81f3da",
   "metadata": {},
   "outputs": [],
   "source": [
    "\n",
    "TransformedEquipmentData"
   ]
  },
  {
   "cell_type": "code",
   "execution_count": 14,
   "id": "4c6f52b8-e8c4-4c5e-8d5b-186af8414bee",
   "metadata": {},
   "outputs": [
    {
     "name": "stdout",
     "output_type": "stream",
     "text": [
      "Requirement already satisfied: snowflake-connector-python in /opt/conda/lib/python3.9/site-packages (3.12.1)\n",
      "Requirement already satisfied: asn1crypto<2.0.0,>0.24.0 in /opt/conda/lib/python3.9/site-packages (from snowflake-connector-python) (1.5.1)\n",
      "Requirement already satisfied: platformdirs<5.0.0,>=2.6.0 in /opt/conda/lib/python3.9/site-packages (from snowflake-connector-python) (4.2.2)\n",
      "Requirement already satisfied: tomlkit in /opt/conda/lib/python3.9/site-packages (from snowflake-connector-python) (0.13.2)\n",
      "Requirement already satisfied: pyjwt<3.0.0 in /opt/conda/lib/python3.9/site-packages (from snowflake-connector-python) (2.9.0)\n",
      "Requirement already satisfied: pyOpenSSL<25.0.0,>=16.2.0 in /opt/conda/lib/python3.9/site-packages (from snowflake-connector-python) (24.0.0)\n",
      "Requirement already satisfied: filelock<4,>=3.5 in /opt/conda/lib/python3.9/site-packages (from snowflake-connector-python) (3.15.4)\n",
      "Requirement already satisfied: certifi>=2017.4.17 in /opt/conda/lib/python3.9/site-packages (from snowflake-connector-python) (2024.7.4)\n",
      "Requirement already satisfied: sortedcontainers>=2.4.0 in /opt/conda/lib/python3.9/site-packages (from snowflake-connector-python) (2.4.0)\n",
      "Requirement already satisfied: urllib3<2.0.0,>=1.21.1; python_version < \"3.10\" in /opt/conda/lib/python3.9/site-packages (from snowflake-connector-python) (1.26.19)\n",
      "Requirement already satisfied: requests<3.0.0 in /opt/conda/lib/python3.9/site-packages (from snowflake-connector-python) (2.32.3)\n",
      "Requirement already satisfied: pytz in /opt/conda/lib/python3.9/site-packages (from snowflake-connector-python) (2024.1)\n",
      "Requirement already satisfied: typing-extensions<5,>=4.3 in /opt/conda/lib/python3.9/site-packages (from snowflake-connector-python) (4.12.2)\n",
      "Requirement already satisfied: charset-normalizer<4,>=2 in /opt/conda/lib/python3.9/site-packages (from snowflake-connector-python) (3.3.2)\n",
      "Requirement already satisfied: cryptography>=3.1.0 in /opt/conda/lib/python3.9/site-packages (from snowflake-connector-python) (42.0.5)\n",
      "Requirement already satisfied: packaging in /opt/conda/lib/python3.9/site-packages (from snowflake-connector-python) (23.2)\n",
      "Requirement already satisfied: idna<4,>=2.5 in /opt/conda/lib/python3.9/site-packages (from snowflake-connector-python) (3.7)\n",
      "Requirement already satisfied: cffi<2.0.0,>=1.9 in /opt/conda/lib/python3.9/site-packages (from snowflake-connector-python) (1.16.0)\n",
      "Requirement already satisfied: pycparser in /opt/conda/lib/python3.9/site-packages (from cffi<2.0.0,>=1.9->snowflake-connector-python) (2.21)\n",
      "\u001b[33mWARNING: You are using pip version 19.3.1; however, version 24.2 is available.\n",
      "You should consider upgrading via the 'pip install --upgrade pip' command.\u001b[0m\n"
     ]
    }
   ],
   "source": [
    "!pip install snowflake-connector-python"
   ]
  },
  {
   "cell_type": "code",
   "execution_count": 20,
   "id": "8781b77e-640a-49ca-9b8c-41a57e533da0",
   "metadata": {},
   "outputs": [
    {
     "ename": "OperationalError",
     "evalue": "250001: Could not connect to Snowflake backend after 2 attempt(s).Aborting",
     "output_type": "error",
     "traceback": [
      "\u001b[0;31m---------------------------------------------------------------------------\u001b[0m",
      "\u001b[0;31mgaierror\u001b[0m                                  Traceback (most recent call last)",
      "File \u001b[0;32m/opt/conda/lib/python3.9/site-packages/snowflake/connector/vendored/urllib3/connection.py:174\u001b[0m, in \u001b[0;36mHTTPConnection._new_conn\u001b[0;34m(self)\u001b[0m\n\u001b[1;32m    173\u001b[0m \u001b[38;5;28;01mtry\u001b[39;00m:\n\u001b[0;32m--> 174\u001b[0m     conn \u001b[38;5;241m=\u001b[39m \u001b[43mconnection\u001b[49m\u001b[38;5;241;43m.\u001b[39;49m\u001b[43mcreate_connection\u001b[49m\u001b[43m(\u001b[49m\n\u001b[1;32m    175\u001b[0m \u001b[43m        \u001b[49m\u001b[43m(\u001b[49m\u001b[38;5;28;43mself\u001b[39;49m\u001b[38;5;241;43m.\u001b[39;49m\u001b[43m_dns_host\u001b[49m\u001b[43m,\u001b[49m\u001b[43m \u001b[49m\u001b[38;5;28;43mself\u001b[39;49m\u001b[38;5;241;43m.\u001b[39;49m\u001b[43mport\u001b[49m\u001b[43m)\u001b[49m\u001b[43m,\u001b[49m\u001b[43m \u001b[49m\u001b[38;5;28;43mself\u001b[39;49m\u001b[38;5;241;43m.\u001b[39;49m\u001b[43mtimeout\u001b[49m\u001b[43m,\u001b[49m\u001b[43m \u001b[49m\u001b[38;5;241;43m*\u001b[39;49m\u001b[38;5;241;43m*\u001b[39;49m\u001b[43mextra_kw\u001b[49m\n\u001b[1;32m    176\u001b[0m \u001b[43m    \u001b[49m\u001b[43m)\u001b[49m\n\u001b[1;32m    178\u001b[0m \u001b[38;5;28;01mexcept\u001b[39;00m SocketTimeout:\n",
      "File \u001b[0;32m/opt/conda/lib/python3.9/site-packages/snowflake/connector/vendored/urllib3/util/connection.py:79\u001b[0m, in \u001b[0;36mcreate_connection\u001b[0;34m(address, timeout, source_address, socket_options)\u001b[0m\n\u001b[1;32m     75\u001b[0m     \u001b[38;5;28;01mreturn\u001b[39;00m six\u001b[38;5;241m.\u001b[39mraise_from(\n\u001b[1;32m     76\u001b[0m         LocationParseError(\u001b[38;5;124mu\u001b[39m\u001b[38;5;124m\"\u001b[39m\u001b[38;5;124m'\u001b[39m\u001b[38;5;132;01m%s\u001b[39;00m\u001b[38;5;124m'\u001b[39m\u001b[38;5;124m, label empty or too long\u001b[39m\u001b[38;5;124m\"\u001b[39m \u001b[38;5;241m%\u001b[39m host), \u001b[38;5;28;01mNone\u001b[39;00m\n\u001b[1;32m     77\u001b[0m     )\n\u001b[0;32m---> 79\u001b[0m \u001b[38;5;28;01mfor\u001b[39;00m res \u001b[38;5;129;01min\u001b[39;00m \u001b[43msocket\u001b[49m\u001b[38;5;241;43m.\u001b[39;49m\u001b[43mgetaddrinfo\u001b[49m\u001b[43m(\u001b[49m\u001b[43mhost\u001b[49m\u001b[43m,\u001b[49m\u001b[43m \u001b[49m\u001b[43mport\u001b[49m\u001b[43m,\u001b[49m\u001b[43m \u001b[49m\u001b[43mfamily\u001b[49m\u001b[43m,\u001b[49m\u001b[43m \u001b[49m\u001b[43msocket\u001b[49m\u001b[38;5;241;43m.\u001b[39;49m\u001b[43mSOCK_STREAM\u001b[49m\u001b[43m)\u001b[49m:\n\u001b[1;32m     80\u001b[0m     af, socktype, proto, canonname, sa \u001b[38;5;241m=\u001b[39m res\n",
      "File \u001b[0;32m/opt/conda/lib/python3.9/socket.py:954\u001b[0m, in \u001b[0;36mgetaddrinfo\u001b[0;34m(host, port, family, type, proto, flags)\u001b[0m\n\u001b[1;32m    953\u001b[0m addrlist \u001b[38;5;241m=\u001b[39m []\n\u001b[0;32m--> 954\u001b[0m \u001b[38;5;28;01mfor\u001b[39;00m res \u001b[38;5;129;01min\u001b[39;00m \u001b[43m_socket\u001b[49m\u001b[38;5;241;43m.\u001b[39;49m\u001b[43mgetaddrinfo\u001b[49m\u001b[43m(\u001b[49m\u001b[43mhost\u001b[49m\u001b[43m,\u001b[49m\u001b[43m \u001b[49m\u001b[43mport\u001b[49m\u001b[43m,\u001b[49m\u001b[43m \u001b[49m\u001b[43mfamily\u001b[49m\u001b[43m,\u001b[49m\u001b[43m \u001b[49m\u001b[38;5;28;43mtype\u001b[39;49m\u001b[43m,\u001b[49m\u001b[43m \u001b[49m\u001b[43mproto\u001b[49m\u001b[43m,\u001b[49m\u001b[43m \u001b[49m\u001b[43mflags\u001b[49m\u001b[43m)\u001b[49m:\n\u001b[1;32m    955\u001b[0m     af, socktype, proto, canonname, sa \u001b[38;5;241m=\u001b[39m res\n",
      "\u001b[0;31mgaierror\u001b[0m: [Errno -2] Name or service not known",
      "\nDuring handling of the above exception, another exception occurred:\n",
      "\u001b[0;31mNewConnectionError\u001b[0m                        Traceback (most recent call last)",
      "File \u001b[0;32m/opt/conda/lib/python3.9/site-packages/snowflake/connector/vendored/urllib3/connectionpool.py:715\u001b[0m, in \u001b[0;36mHTTPConnectionPool.urlopen\u001b[0;34m(self, method, url, body, headers, retries, redirect, assert_same_host, timeout, pool_timeout, release_conn, chunked, body_pos, **response_kw)\u001b[0m\n\u001b[1;32m    714\u001b[0m \u001b[38;5;66;03m# Make the request on the httplib connection object.\u001b[39;00m\n\u001b[0;32m--> 715\u001b[0m httplib_response \u001b[38;5;241m=\u001b[39m \u001b[38;5;28;43mself\u001b[39;49m\u001b[38;5;241;43m.\u001b[39;49m\u001b[43m_make_request\u001b[49m\u001b[43m(\u001b[49m\n\u001b[1;32m    716\u001b[0m \u001b[43m    \u001b[49m\u001b[43mconn\u001b[49m\u001b[43m,\u001b[49m\n\u001b[1;32m    717\u001b[0m \u001b[43m    \u001b[49m\u001b[43mmethod\u001b[49m\u001b[43m,\u001b[49m\n\u001b[1;32m    718\u001b[0m \u001b[43m    \u001b[49m\u001b[43murl\u001b[49m\u001b[43m,\u001b[49m\n\u001b[1;32m    719\u001b[0m \u001b[43m    \u001b[49m\u001b[43mtimeout\u001b[49m\u001b[38;5;241;43m=\u001b[39;49m\u001b[43mtimeout_obj\u001b[49m\u001b[43m,\u001b[49m\n\u001b[1;32m    720\u001b[0m \u001b[43m    \u001b[49m\u001b[43mbody\u001b[49m\u001b[38;5;241;43m=\u001b[39;49m\u001b[43mbody\u001b[49m\u001b[43m,\u001b[49m\n\u001b[1;32m    721\u001b[0m \u001b[43m    \u001b[49m\u001b[43mheaders\u001b[49m\u001b[38;5;241;43m=\u001b[39;49m\u001b[43mheaders\u001b[49m\u001b[43m,\u001b[49m\n\u001b[1;32m    722\u001b[0m \u001b[43m    \u001b[49m\u001b[43mchunked\u001b[49m\u001b[38;5;241;43m=\u001b[39;49m\u001b[43mchunked\u001b[49m\u001b[43m,\u001b[49m\n\u001b[1;32m    723\u001b[0m \u001b[43m\u001b[49m\u001b[43m)\u001b[49m\n\u001b[1;32m    725\u001b[0m \u001b[38;5;66;03m# If we're going to release the connection in ``finally:``, then\u001b[39;00m\n\u001b[1;32m    726\u001b[0m \u001b[38;5;66;03m# the response doesn't need to know about the connection. Otherwise\u001b[39;00m\n\u001b[1;32m    727\u001b[0m \u001b[38;5;66;03m# it will also try to release it and we'll have a double-release\u001b[39;00m\n\u001b[1;32m    728\u001b[0m \u001b[38;5;66;03m# mess.\u001b[39;00m\n",
      "File \u001b[0;32m/opt/conda/lib/python3.9/site-packages/snowflake/connector/vendored/urllib3/connectionpool.py:404\u001b[0m, in \u001b[0;36mHTTPConnectionPool._make_request\u001b[0;34m(self, conn, method, url, timeout, chunked, **httplib_request_kw)\u001b[0m\n\u001b[1;32m    403\u001b[0m \u001b[38;5;28;01mtry\u001b[39;00m:\n\u001b[0;32m--> 404\u001b[0m     \u001b[38;5;28;43mself\u001b[39;49m\u001b[38;5;241;43m.\u001b[39;49m\u001b[43m_validate_conn\u001b[49m\u001b[43m(\u001b[49m\u001b[43mconn\u001b[49m\u001b[43m)\u001b[49m\n\u001b[1;32m    405\u001b[0m \u001b[38;5;28;01mexcept\u001b[39;00m (SocketTimeout, BaseSSLError) \u001b[38;5;28;01mas\u001b[39;00m e:\n\u001b[1;32m    406\u001b[0m     \u001b[38;5;66;03m# Py2 raises this as a BaseSSLError, Py3 raises it as socket timeout.\u001b[39;00m\n",
      "File \u001b[0;32m/opt/conda/lib/python3.9/site-packages/snowflake/connector/vendored/urllib3/connectionpool.py:1058\u001b[0m, in \u001b[0;36mHTTPSConnectionPool._validate_conn\u001b[0;34m(self, conn)\u001b[0m\n\u001b[1;32m   1057\u001b[0m \u001b[38;5;28;01mif\u001b[39;00m \u001b[38;5;129;01mnot\u001b[39;00m \u001b[38;5;28mgetattr\u001b[39m(conn, \u001b[38;5;124m\"\u001b[39m\u001b[38;5;124msock\u001b[39m\u001b[38;5;124m\"\u001b[39m, \u001b[38;5;28;01mNone\u001b[39;00m):  \u001b[38;5;66;03m# AppEngine might not have  `.sock`\u001b[39;00m\n\u001b[0;32m-> 1058\u001b[0m     \u001b[43mconn\u001b[49m\u001b[38;5;241;43m.\u001b[39;49m\u001b[43mconnect\u001b[49m\u001b[43m(\u001b[49m\u001b[43m)\u001b[49m\n\u001b[1;32m   1060\u001b[0m \u001b[38;5;28;01mif\u001b[39;00m \u001b[38;5;129;01mnot\u001b[39;00m conn\u001b[38;5;241m.\u001b[39mis_verified:\n",
      "File \u001b[0;32m/opt/conda/lib/python3.9/site-packages/snowflake/connector/vendored/urllib3/connection.py:363\u001b[0m, in \u001b[0;36mHTTPSConnection.connect\u001b[0;34m(self)\u001b[0m\n\u001b[1;32m    361\u001b[0m \u001b[38;5;28;01mdef\u001b[39;00m \u001b[38;5;21mconnect\u001b[39m(\u001b[38;5;28mself\u001b[39m):\n\u001b[1;32m    362\u001b[0m     \u001b[38;5;66;03m# Add certificate verification\u001b[39;00m\n\u001b[0;32m--> 363\u001b[0m     \u001b[38;5;28mself\u001b[39m\u001b[38;5;241m.\u001b[39msock \u001b[38;5;241m=\u001b[39m conn \u001b[38;5;241m=\u001b[39m \u001b[38;5;28;43mself\u001b[39;49m\u001b[38;5;241;43m.\u001b[39;49m\u001b[43m_new_conn\u001b[49m\u001b[43m(\u001b[49m\u001b[43m)\u001b[49m\n\u001b[1;32m    364\u001b[0m     hostname \u001b[38;5;241m=\u001b[39m \u001b[38;5;28mself\u001b[39m\u001b[38;5;241m.\u001b[39mhost\n",
      "File \u001b[0;32m/opt/conda/lib/python3.9/site-packages/snowflake/connector/vendored/urllib3/connection.py:186\u001b[0m, in \u001b[0;36mHTTPConnection._new_conn\u001b[0;34m(self)\u001b[0m\n\u001b[1;32m    185\u001b[0m \u001b[38;5;28;01mexcept\u001b[39;00m SocketError \u001b[38;5;28;01mas\u001b[39;00m e:\n\u001b[0;32m--> 186\u001b[0m     \u001b[38;5;28;01mraise\u001b[39;00m NewConnectionError(\n\u001b[1;32m    187\u001b[0m         \u001b[38;5;28mself\u001b[39m, \u001b[38;5;124m\"\u001b[39m\u001b[38;5;124mFailed to establish a new connection: \u001b[39m\u001b[38;5;132;01m%s\u001b[39;00m\u001b[38;5;124m\"\u001b[39m \u001b[38;5;241m%\u001b[39m e\n\u001b[1;32m    188\u001b[0m     )\n\u001b[1;32m    190\u001b[0m \u001b[38;5;28;01mreturn\u001b[39;00m conn\n",
      "\u001b[0;31mNewConnectionError\u001b[0m: <snowflake.connector.vendored.urllib3.connection.HTTPSConnection object at 0x7f124440deb0>: Failed to establish a new connection: [Errno -2] Name or service not known",
      "\nDuring handling of the above exception, another exception occurred:\n",
      "\u001b[0;31mMaxRetryError\u001b[0m                             Traceback (most recent call last)",
      "File \u001b[0;32m/opt/conda/lib/python3.9/site-packages/snowflake/connector/vendored/requests/adapters.py:486\u001b[0m, in \u001b[0;36mHTTPAdapter.send\u001b[0;34m(self, request, stream, timeout, verify, cert, proxies)\u001b[0m\n\u001b[1;32m    485\u001b[0m \u001b[38;5;28;01mtry\u001b[39;00m:\n\u001b[0;32m--> 486\u001b[0m     resp \u001b[38;5;241m=\u001b[39m \u001b[43mconn\u001b[49m\u001b[38;5;241;43m.\u001b[39;49m\u001b[43murlopen\u001b[49m\u001b[43m(\u001b[49m\n\u001b[1;32m    487\u001b[0m \u001b[43m        \u001b[49m\u001b[43mmethod\u001b[49m\u001b[38;5;241;43m=\u001b[39;49m\u001b[43mrequest\u001b[49m\u001b[38;5;241;43m.\u001b[39;49m\u001b[43mmethod\u001b[49m\u001b[43m,\u001b[49m\n\u001b[1;32m    488\u001b[0m \u001b[43m        \u001b[49m\u001b[43murl\u001b[49m\u001b[38;5;241;43m=\u001b[39;49m\u001b[43murl\u001b[49m\u001b[43m,\u001b[49m\n\u001b[1;32m    489\u001b[0m \u001b[43m        \u001b[49m\u001b[43mbody\u001b[49m\u001b[38;5;241;43m=\u001b[39;49m\u001b[43mrequest\u001b[49m\u001b[38;5;241;43m.\u001b[39;49m\u001b[43mbody\u001b[49m\u001b[43m,\u001b[49m\n\u001b[1;32m    490\u001b[0m \u001b[43m        \u001b[49m\u001b[43mheaders\u001b[49m\u001b[38;5;241;43m=\u001b[39;49m\u001b[43mrequest\u001b[49m\u001b[38;5;241;43m.\u001b[39;49m\u001b[43mheaders\u001b[49m\u001b[43m,\u001b[49m\n\u001b[1;32m    491\u001b[0m \u001b[43m        \u001b[49m\u001b[43mredirect\u001b[49m\u001b[38;5;241;43m=\u001b[39;49m\u001b[38;5;28;43;01mFalse\u001b[39;49;00m\u001b[43m,\u001b[49m\n\u001b[1;32m    492\u001b[0m \u001b[43m        \u001b[49m\u001b[43massert_same_host\u001b[49m\u001b[38;5;241;43m=\u001b[39;49m\u001b[38;5;28;43;01mFalse\u001b[39;49;00m\u001b[43m,\u001b[49m\n\u001b[1;32m    493\u001b[0m \u001b[43m        \u001b[49m\u001b[43mpreload_content\u001b[49m\u001b[38;5;241;43m=\u001b[39;49m\u001b[38;5;28;43;01mFalse\u001b[39;49;00m\u001b[43m,\u001b[49m\n\u001b[1;32m    494\u001b[0m \u001b[43m        \u001b[49m\u001b[43mdecode_content\u001b[49m\u001b[38;5;241;43m=\u001b[39;49m\u001b[38;5;28;43;01mFalse\u001b[39;49;00m\u001b[43m,\u001b[49m\n\u001b[1;32m    495\u001b[0m \u001b[43m        \u001b[49m\u001b[43mretries\u001b[49m\u001b[38;5;241;43m=\u001b[39;49m\u001b[38;5;28;43mself\u001b[39;49m\u001b[38;5;241;43m.\u001b[39;49m\u001b[43mmax_retries\u001b[49m\u001b[43m,\u001b[49m\n\u001b[1;32m    496\u001b[0m \u001b[43m        \u001b[49m\u001b[43mtimeout\u001b[49m\u001b[38;5;241;43m=\u001b[39;49m\u001b[43mtimeout\u001b[49m\u001b[43m,\u001b[49m\n\u001b[1;32m    497\u001b[0m \u001b[43m        \u001b[49m\u001b[43mchunked\u001b[49m\u001b[38;5;241;43m=\u001b[39;49m\u001b[43mchunked\u001b[49m\u001b[43m,\u001b[49m\n\u001b[1;32m    498\u001b[0m \u001b[43m    \u001b[49m\u001b[43m)\u001b[49m\n\u001b[1;32m    500\u001b[0m \u001b[38;5;28;01mexcept\u001b[39;00m (ProtocolError, \u001b[38;5;167;01mOSError\u001b[39;00m) \u001b[38;5;28;01mas\u001b[39;00m err:\n",
      "File \u001b[0;32m/opt/conda/lib/python3.9/site-packages/snowflake/connector/vendored/urllib3/connectionpool.py:827\u001b[0m, in \u001b[0;36mHTTPConnectionPool.urlopen\u001b[0;34m(self, method, url, body, headers, retries, redirect, assert_same_host, timeout, pool_timeout, release_conn, chunked, body_pos, **response_kw)\u001b[0m\n\u001b[1;32m    824\u001b[0m     log\u001b[38;5;241m.\u001b[39mwarning(\n\u001b[1;32m    825\u001b[0m         \u001b[38;5;124m\"\u001b[39m\u001b[38;5;124mRetrying (\u001b[39m\u001b[38;5;132;01m%r\u001b[39;00m\u001b[38;5;124m) after connection broken by \u001b[39m\u001b[38;5;124m'\u001b[39m\u001b[38;5;132;01m%r\u001b[39;00m\u001b[38;5;124m'\u001b[39m\u001b[38;5;124m: \u001b[39m\u001b[38;5;132;01m%s\u001b[39;00m\u001b[38;5;124m\"\u001b[39m, retries, err, url\n\u001b[1;32m    826\u001b[0m     )\n\u001b[0;32m--> 827\u001b[0m     \u001b[38;5;28;01mreturn\u001b[39;00m \u001b[38;5;28;43mself\u001b[39;49m\u001b[38;5;241;43m.\u001b[39;49m\u001b[43murlopen\u001b[49m\u001b[43m(\u001b[49m\n\u001b[1;32m    828\u001b[0m \u001b[43m        \u001b[49m\u001b[43mmethod\u001b[49m\u001b[43m,\u001b[49m\n\u001b[1;32m    829\u001b[0m \u001b[43m        \u001b[49m\u001b[43murl\u001b[49m\u001b[43m,\u001b[49m\n\u001b[1;32m    830\u001b[0m \u001b[43m        \u001b[49m\u001b[43mbody\u001b[49m\u001b[43m,\u001b[49m\n\u001b[1;32m    831\u001b[0m \u001b[43m        \u001b[49m\u001b[43mheaders\u001b[49m\u001b[43m,\u001b[49m\n\u001b[1;32m    832\u001b[0m \u001b[43m        \u001b[49m\u001b[43mretries\u001b[49m\u001b[43m,\u001b[49m\n\u001b[1;32m    833\u001b[0m \u001b[43m        \u001b[49m\u001b[43mredirect\u001b[49m\u001b[43m,\u001b[49m\n\u001b[1;32m    834\u001b[0m \u001b[43m        \u001b[49m\u001b[43massert_same_host\u001b[49m\u001b[43m,\u001b[49m\n\u001b[1;32m    835\u001b[0m \u001b[43m        \u001b[49m\u001b[43mtimeout\u001b[49m\u001b[38;5;241;43m=\u001b[39;49m\u001b[43mtimeout\u001b[49m\u001b[43m,\u001b[49m\n\u001b[1;32m    836\u001b[0m \u001b[43m        \u001b[49m\u001b[43mpool_timeout\u001b[49m\u001b[38;5;241;43m=\u001b[39;49m\u001b[43mpool_timeout\u001b[49m\u001b[43m,\u001b[49m\n\u001b[1;32m    837\u001b[0m \u001b[43m        \u001b[49m\u001b[43mrelease_conn\u001b[49m\u001b[38;5;241;43m=\u001b[39;49m\u001b[43mrelease_conn\u001b[49m\u001b[43m,\u001b[49m\n\u001b[1;32m    838\u001b[0m \u001b[43m        \u001b[49m\u001b[43mchunked\u001b[49m\u001b[38;5;241;43m=\u001b[39;49m\u001b[43mchunked\u001b[49m\u001b[43m,\u001b[49m\n\u001b[1;32m    839\u001b[0m \u001b[43m        \u001b[49m\u001b[43mbody_pos\u001b[49m\u001b[38;5;241;43m=\u001b[39;49m\u001b[43mbody_pos\u001b[49m\u001b[43m,\u001b[49m\n\u001b[1;32m    840\u001b[0m \u001b[43m        \u001b[49m\u001b[38;5;241;43m*\u001b[39;49m\u001b[38;5;241;43m*\u001b[39;49m\u001b[43mresponse_kw\u001b[49m\n\u001b[1;32m    841\u001b[0m \u001b[43m    \u001b[49m\u001b[43m)\u001b[49m\n\u001b[1;32m    843\u001b[0m \u001b[38;5;66;03m# Handle redirect?\u001b[39;00m\n",
      "File \u001b[0;32m/opt/conda/lib/python3.9/site-packages/snowflake/connector/vendored/urllib3/connectionpool.py:799\u001b[0m, in \u001b[0;36mHTTPConnectionPool.urlopen\u001b[0;34m(self, method, url, body, headers, retries, redirect, assert_same_host, timeout, pool_timeout, release_conn, chunked, body_pos, **response_kw)\u001b[0m\n\u001b[1;32m    797\u001b[0m     e \u001b[38;5;241m=\u001b[39m ProtocolError(\u001b[38;5;124m\"\u001b[39m\u001b[38;5;124mConnection aborted.\u001b[39m\u001b[38;5;124m\"\u001b[39m, e)\n\u001b[0;32m--> 799\u001b[0m retries \u001b[38;5;241m=\u001b[39m \u001b[43mretries\u001b[49m\u001b[38;5;241;43m.\u001b[39;49m\u001b[43mincrement\u001b[49m\u001b[43m(\u001b[49m\n\u001b[1;32m    800\u001b[0m \u001b[43m    \u001b[49m\u001b[43mmethod\u001b[49m\u001b[43m,\u001b[49m\u001b[43m \u001b[49m\u001b[43murl\u001b[49m\u001b[43m,\u001b[49m\u001b[43m \u001b[49m\u001b[43merror\u001b[49m\u001b[38;5;241;43m=\u001b[39;49m\u001b[43me\u001b[49m\u001b[43m,\u001b[49m\u001b[43m \u001b[49m\u001b[43m_pool\u001b[49m\u001b[38;5;241;43m=\u001b[39;49m\u001b[38;5;28;43mself\u001b[39;49m\u001b[43m,\u001b[49m\u001b[43m \u001b[49m\u001b[43m_stacktrace\u001b[49m\u001b[38;5;241;43m=\u001b[39;49m\u001b[43msys\u001b[49m\u001b[38;5;241;43m.\u001b[39;49m\u001b[43mexc_info\u001b[49m\u001b[43m(\u001b[49m\u001b[43m)\u001b[49m\u001b[43m[\u001b[49m\u001b[38;5;241;43m2\u001b[39;49m\u001b[43m]\u001b[49m\n\u001b[1;32m    801\u001b[0m \u001b[43m\u001b[49m\u001b[43m)\u001b[49m\n\u001b[1;32m    802\u001b[0m retries\u001b[38;5;241m.\u001b[39msleep()\n",
      "File \u001b[0;32m/opt/conda/lib/python3.9/site-packages/snowflake/connector/vendored/urllib3/util/retry.py:592\u001b[0m, in \u001b[0;36mRetry.increment\u001b[0;34m(self, method, url, response, error, _pool, _stacktrace)\u001b[0m\n\u001b[1;32m    591\u001b[0m \u001b[38;5;28;01mif\u001b[39;00m new_retry\u001b[38;5;241m.\u001b[39mis_exhausted():\n\u001b[0;32m--> 592\u001b[0m     \u001b[38;5;28;01mraise\u001b[39;00m MaxRetryError(_pool, url, error \u001b[38;5;129;01mor\u001b[39;00m ResponseError(cause))\n\u001b[1;32m    594\u001b[0m log\u001b[38;5;241m.\u001b[39mdebug(\u001b[38;5;124m\"\u001b[39m\u001b[38;5;124mIncremented Retry for (url=\u001b[39m\u001b[38;5;124m'\u001b[39m\u001b[38;5;132;01m%s\u001b[39;00m\u001b[38;5;124m'\u001b[39m\u001b[38;5;124m): \u001b[39m\u001b[38;5;132;01m%r\u001b[39;00m\u001b[38;5;124m\"\u001b[39m, url, new_retry)\n",
      "\u001b[0;31mMaxRetryError\u001b[0m: HTTPSConnectionPool(host='https', port=443): Max retries exceeded with url: //fya62509.us-east-1.snowflakecomputing.com:443/session/v1/login-request?request_id=22184bbd-8c0a-4406-9341-317155148c5b&databaseName=RAVI_TESTING&schemaName=RAVI_TESTING (Caused by NewConnectionError('<snowflake.connector.vendored.urllib3.connection.HTTPSConnection object at 0x7f124440deb0>: Failed to establish a new connection: [Errno -2] Name or service not known'))",
      "\nDuring handling of the above exception, another exception occurred:\n",
      "\u001b[0;31mConnectionError\u001b[0m                           Traceback (most recent call last)",
      "File \u001b[0;32m/opt/conda/lib/python3.9/site-packages/snowflake/connector/network.py:1059\u001b[0m, in \u001b[0;36mSnowflakeRestful._request_exec\u001b[0;34m(self, session, method, full_url, headers, data, token, catch_okta_unauthorized_error, is_raw_text, is_raw_binary, binary_data_handler, socket_timeout, is_okta_authentication)\u001b[0m\n\u001b[1;32m   1056\u001b[0m \u001b[38;5;66;03m# socket timeout is constant. You should be able to receive\u001b[39;00m\n\u001b[1;32m   1057\u001b[0m \u001b[38;5;66;03m# the response within the time. If not, ConnectReadTimeout or\u001b[39;00m\n\u001b[1;32m   1058\u001b[0m \u001b[38;5;66;03m# ReadTimeout is raised.\u001b[39;00m\n\u001b[0;32m-> 1059\u001b[0m raw_ret \u001b[38;5;241m=\u001b[39m \u001b[43msession\u001b[49m\u001b[38;5;241;43m.\u001b[39;49m\u001b[43mrequest\u001b[49m\u001b[43m(\u001b[49m\n\u001b[1;32m   1060\u001b[0m \u001b[43m    \u001b[49m\u001b[43mmethod\u001b[49m\u001b[38;5;241;43m=\u001b[39;49m\u001b[43mmethod\u001b[49m\u001b[43m,\u001b[49m\n\u001b[1;32m   1061\u001b[0m \u001b[43m    \u001b[49m\u001b[43murl\u001b[49m\u001b[38;5;241;43m=\u001b[39;49m\u001b[43mfull_url\u001b[49m\u001b[43m,\u001b[49m\n\u001b[1;32m   1062\u001b[0m \u001b[43m    \u001b[49m\u001b[43mheaders\u001b[49m\u001b[38;5;241;43m=\u001b[39;49m\u001b[43mheaders\u001b[49m\u001b[43m,\u001b[49m\n\u001b[1;32m   1063\u001b[0m \u001b[43m    \u001b[49m\u001b[43mdata\u001b[49m\u001b[38;5;241;43m=\u001b[39;49m\u001b[43minput_data\u001b[49m\u001b[43m,\u001b[49m\n\u001b[1;32m   1064\u001b[0m \u001b[43m    \u001b[49m\u001b[43mtimeout\u001b[49m\u001b[38;5;241;43m=\u001b[39;49m\u001b[43msocket_timeout\u001b[49m\u001b[43m,\u001b[49m\n\u001b[1;32m   1065\u001b[0m \u001b[43m    \u001b[49m\u001b[43mverify\u001b[49m\u001b[38;5;241;43m=\u001b[39;49m\u001b[38;5;28;43;01mTrue\u001b[39;49;00m\u001b[43m,\u001b[49m\n\u001b[1;32m   1066\u001b[0m \u001b[43m    \u001b[49m\u001b[43mstream\u001b[49m\u001b[38;5;241;43m=\u001b[39;49m\u001b[43mis_raw_binary\u001b[49m\u001b[43m,\u001b[49m\n\u001b[1;32m   1067\u001b[0m \u001b[43m    \u001b[49m\u001b[43mauth\u001b[49m\u001b[38;5;241;43m=\u001b[39;49m\u001b[43mSnowflakeAuth\u001b[49m\u001b[43m(\u001b[49m\u001b[43mtoken\u001b[49m\u001b[43m)\u001b[49m\u001b[43m,\u001b[49m\n\u001b[1;32m   1068\u001b[0m \u001b[43m\u001b[49m\u001b[43m)\u001b[49m\n\u001b[1;32m   1069\u001b[0m download_end_time \u001b[38;5;241m=\u001b[39m get_time_millis()\n",
      "File \u001b[0;32m/opt/conda/lib/python3.9/site-packages/snowflake/connector/vendored/requests/sessions.py:589\u001b[0m, in \u001b[0;36mSession.request\u001b[0;34m(self, method, url, params, data, headers, cookies, files, auth, timeout, allow_redirects, proxies, hooks, stream, verify, cert, json)\u001b[0m\n\u001b[1;32m    588\u001b[0m send_kwargs\u001b[38;5;241m.\u001b[39mupdate(settings)\n\u001b[0;32m--> 589\u001b[0m resp \u001b[38;5;241m=\u001b[39m \u001b[38;5;28;43mself\u001b[39;49m\u001b[38;5;241;43m.\u001b[39;49m\u001b[43msend\u001b[49m\u001b[43m(\u001b[49m\u001b[43mprep\u001b[49m\u001b[43m,\u001b[49m\u001b[43m \u001b[49m\u001b[38;5;241;43m*\u001b[39;49m\u001b[38;5;241;43m*\u001b[39;49m\u001b[43msend_kwargs\u001b[49m\u001b[43m)\u001b[49m\n\u001b[1;32m    591\u001b[0m \u001b[38;5;28;01mreturn\u001b[39;00m resp\n",
      "File \u001b[0;32m/opt/conda/lib/python3.9/site-packages/snowflake/connector/vendored/requests/sessions.py:703\u001b[0m, in \u001b[0;36mSession.send\u001b[0;34m(self, request, **kwargs)\u001b[0m\n\u001b[1;32m    702\u001b[0m \u001b[38;5;66;03m# Send the request\u001b[39;00m\n\u001b[0;32m--> 703\u001b[0m r \u001b[38;5;241m=\u001b[39m \u001b[43madapter\u001b[49m\u001b[38;5;241;43m.\u001b[39;49m\u001b[43msend\u001b[49m\u001b[43m(\u001b[49m\u001b[43mrequest\u001b[49m\u001b[43m,\u001b[49m\u001b[43m \u001b[49m\u001b[38;5;241;43m*\u001b[39;49m\u001b[38;5;241;43m*\u001b[39;49m\u001b[43mkwargs\u001b[49m\u001b[43m)\u001b[49m\n\u001b[1;32m    705\u001b[0m \u001b[38;5;66;03m# Total elapsed time of the request (approximately)\u001b[39;00m\n",
      "File \u001b[0;32m/opt/conda/lib/python3.9/site-packages/snowflake/connector/vendored/requests/adapters.py:519\u001b[0m, in \u001b[0;36mHTTPAdapter.send\u001b[0;34m(self, request, stream, timeout, verify, cert, proxies)\u001b[0m\n\u001b[1;32m    517\u001b[0m         \u001b[38;5;28;01mraise\u001b[39;00m SSLError(e, request\u001b[38;5;241m=\u001b[39mrequest)\n\u001b[0;32m--> 519\u001b[0m     \u001b[38;5;28;01mraise\u001b[39;00m \u001b[38;5;167;01mConnectionError\u001b[39;00m(e, request\u001b[38;5;241m=\u001b[39mrequest)\n\u001b[1;32m    521\u001b[0m \u001b[38;5;28;01mexcept\u001b[39;00m ClosedPoolError \u001b[38;5;28;01mas\u001b[39;00m e:\n",
      "\u001b[0;31mConnectionError\u001b[0m: HTTPSConnectionPool(host='https', port=443): Max retries exceeded with url: //fya62509.us-east-1.snowflakecomputing.com:443/session/v1/login-request?request_id=22184bbd-8c0a-4406-9341-317155148c5b&databaseName=RAVI_TESTING&schemaName=RAVI_TESTING (Caused by NewConnectionError('<snowflake.connector.vendored.urllib3.connection.HTTPSConnection object at 0x7f124440deb0>: Failed to establish a new connection: [Errno -2] Name or service not known'))",
      "\nDuring handling of the above exception, another exception occurred:\n",
      "\u001b[0;31mOperationalError\u001b[0m                          Traceback (most recent call last)",
      "File \u001b[0;32m/opt/conda/lib/python3.9/site-packages/snowflake/connector/connection.py:1414\u001b[0m, in \u001b[0;36mSnowflakeConnection._authenticate\u001b[0;34m(self, auth_instance)\u001b[0m\n\u001b[1;32m   1413\u001b[0m \u001b[38;5;28;01mtry\u001b[39;00m:\n\u001b[0;32m-> 1414\u001b[0m     \u001b[43mauth\u001b[49m\u001b[38;5;241;43m.\u001b[39;49m\u001b[43mauthenticate\u001b[49m\u001b[43m(\u001b[49m\n\u001b[1;32m   1415\u001b[0m \u001b[43m        \u001b[49m\u001b[43mauth_instance\u001b[49m\u001b[38;5;241;43m=\u001b[39;49m\u001b[43mauth_instance\u001b[49m\u001b[43m,\u001b[49m\n\u001b[1;32m   1416\u001b[0m \u001b[43m        \u001b[49m\u001b[43maccount\u001b[49m\u001b[38;5;241;43m=\u001b[39;49m\u001b[38;5;28;43mself\u001b[39;49m\u001b[38;5;241;43m.\u001b[39;49m\u001b[43maccount\u001b[49m\u001b[43m,\u001b[49m\n\u001b[1;32m   1417\u001b[0m \u001b[43m        \u001b[49m\u001b[43muser\u001b[49m\u001b[38;5;241;43m=\u001b[39;49m\u001b[38;5;28;43mself\u001b[39;49m\u001b[38;5;241;43m.\u001b[39;49m\u001b[43muser\u001b[49m\u001b[43m,\u001b[49m\n\u001b[1;32m   1418\u001b[0m \u001b[43m        \u001b[49m\u001b[43mdatabase\u001b[49m\u001b[38;5;241;43m=\u001b[39;49m\u001b[38;5;28;43mself\u001b[39;49m\u001b[38;5;241;43m.\u001b[39;49m\u001b[43mdatabase\u001b[49m\u001b[43m,\u001b[49m\n\u001b[1;32m   1419\u001b[0m \u001b[43m        \u001b[49m\u001b[43mschema\u001b[49m\u001b[38;5;241;43m=\u001b[39;49m\u001b[38;5;28;43mself\u001b[39;49m\u001b[38;5;241;43m.\u001b[39;49m\u001b[43mschema\u001b[49m\u001b[43m,\u001b[49m\n\u001b[1;32m   1420\u001b[0m \u001b[43m        \u001b[49m\u001b[43mwarehouse\u001b[49m\u001b[38;5;241;43m=\u001b[39;49m\u001b[38;5;28;43mself\u001b[39;49m\u001b[38;5;241;43m.\u001b[39;49m\u001b[43mwarehouse\u001b[49m\u001b[43m,\u001b[49m\n\u001b[1;32m   1421\u001b[0m \u001b[43m        \u001b[49m\u001b[43mrole\u001b[49m\u001b[38;5;241;43m=\u001b[39;49m\u001b[38;5;28;43mself\u001b[39;49m\u001b[38;5;241;43m.\u001b[39;49m\u001b[43mrole\u001b[49m\u001b[43m,\u001b[49m\n\u001b[1;32m   1422\u001b[0m \u001b[43m        \u001b[49m\u001b[43mpasscode\u001b[49m\u001b[38;5;241;43m=\u001b[39;49m\u001b[38;5;28;43mself\u001b[39;49m\u001b[38;5;241;43m.\u001b[39;49m\u001b[43m_passcode\u001b[49m\u001b[43m,\u001b[49m\n\u001b[1;32m   1423\u001b[0m \u001b[43m        \u001b[49m\u001b[43mpasscode_in_password\u001b[49m\u001b[38;5;241;43m=\u001b[39;49m\u001b[38;5;28;43mself\u001b[39;49m\u001b[38;5;241;43m.\u001b[39;49m\u001b[43m_passcode_in_password\u001b[49m\u001b[43m,\u001b[49m\n\u001b[1;32m   1424\u001b[0m \u001b[43m        \u001b[49m\u001b[43mmfa_callback\u001b[49m\u001b[38;5;241;43m=\u001b[39;49m\u001b[38;5;28;43mself\u001b[39;49m\u001b[38;5;241;43m.\u001b[39;49m\u001b[43m_mfa_callback\u001b[49m\u001b[43m,\u001b[49m\n\u001b[1;32m   1425\u001b[0m \u001b[43m        \u001b[49m\u001b[43mpassword_callback\u001b[49m\u001b[38;5;241;43m=\u001b[39;49m\u001b[38;5;28;43mself\u001b[39;49m\u001b[38;5;241;43m.\u001b[39;49m\u001b[43m_password_callback\u001b[49m\u001b[43m,\u001b[49m\n\u001b[1;32m   1426\u001b[0m \u001b[43m        \u001b[49m\u001b[43msession_parameters\u001b[49m\u001b[38;5;241;43m=\u001b[39;49m\u001b[38;5;28;43mself\u001b[39;49m\u001b[38;5;241;43m.\u001b[39;49m\u001b[43m_session_parameters\u001b[49m\u001b[43m,\u001b[49m\n\u001b[1;32m   1427\u001b[0m \u001b[43m    \u001b[49m\u001b[43m)\u001b[49m\n\u001b[1;32m   1428\u001b[0m \u001b[38;5;28;01mexcept\u001b[39;00m OperationalError \u001b[38;5;28;01mas\u001b[39;00m e:\n",
      "File \u001b[0;32m/opt/conda/lib/python3.9/site-packages/snowflake/connector/auth/_auth.py:250\u001b[0m, in \u001b[0;36mAuth.authenticate\u001b[0;34m(self, auth_instance, account, user, database, schema, warehouse, role, passcode, passcode_in_password, mfa_callback, password_callback, session_parameters, timeout)\u001b[0m\n\u001b[1;32m    249\u001b[0m \u001b[38;5;28;01mtry\u001b[39;00m:\n\u001b[0;32m--> 250\u001b[0m     ret \u001b[38;5;241m=\u001b[39m \u001b[38;5;28;43mself\u001b[39;49m\u001b[38;5;241;43m.\u001b[39;49m\u001b[43m_rest\u001b[49m\u001b[38;5;241;43m.\u001b[39;49m\u001b[43m_post_request\u001b[49m\u001b[43m(\u001b[49m\n\u001b[1;32m    251\u001b[0m \u001b[43m        \u001b[49m\u001b[43murl\u001b[49m\u001b[43m,\u001b[49m\n\u001b[1;32m    252\u001b[0m \u001b[43m        \u001b[49m\u001b[43mheaders\u001b[49m\u001b[43m,\u001b[49m\n\u001b[1;32m    253\u001b[0m \u001b[43m        \u001b[49m\u001b[43mjson\u001b[49m\u001b[38;5;241;43m.\u001b[39;49m\u001b[43mdumps\u001b[49m\u001b[43m(\u001b[49m\u001b[43mbody\u001b[49m\u001b[43m)\u001b[49m\u001b[43m,\u001b[49m\n\u001b[1;32m    254\u001b[0m \u001b[43m        \u001b[49m\u001b[43msocket_timeout\u001b[49m\u001b[38;5;241;43m=\u001b[39;49m\u001b[43mauth_instance\u001b[49m\u001b[38;5;241;43m.\u001b[39;49m\u001b[43m_socket_timeout\u001b[49m\u001b[43m,\u001b[49m\n\u001b[1;32m    255\u001b[0m \u001b[43m    \u001b[49m\u001b[43m)\u001b[49m\n\u001b[1;32m    256\u001b[0m \u001b[38;5;28;01mexcept\u001b[39;00m ForbiddenError \u001b[38;5;28;01mas\u001b[39;00m err:\n\u001b[1;32m    257\u001b[0m     \u001b[38;5;66;03m# HTTP 403\u001b[39;00m\n",
      "File \u001b[0;32m/opt/conda/lib/python3.9/site-packages/snowflake/connector/network.py:739\u001b[0m, in \u001b[0;36mSnowflakeRestful._post_request\u001b[0;34m(self, url, headers, body, token, timeout, socket_timeout, _no_results, no_retry, _include_retry_params)\u001b[0m\n\u001b[1;32m    737\u001b[0m     pprint(ret)\n\u001b[0;32m--> 739\u001b[0m ret \u001b[38;5;241m=\u001b[39m \u001b[38;5;28;43mself\u001b[39;49m\u001b[38;5;241;43m.\u001b[39;49m\u001b[43mfetch\u001b[49m\u001b[43m(\u001b[49m\n\u001b[1;32m    740\u001b[0m \u001b[43m    \u001b[49m\u001b[38;5;124;43m\"\u001b[39;49m\u001b[38;5;124;43mpost\u001b[39;49m\u001b[38;5;124;43m\"\u001b[39;49m\u001b[43m,\u001b[49m\n\u001b[1;32m    741\u001b[0m \u001b[43m    \u001b[49m\u001b[43mfull_url\u001b[49m\u001b[43m,\u001b[49m\n\u001b[1;32m    742\u001b[0m \u001b[43m    \u001b[49m\u001b[43mheaders\u001b[49m\u001b[43m,\u001b[49m\n\u001b[1;32m    743\u001b[0m \u001b[43m    \u001b[49m\u001b[43mdata\u001b[49m\u001b[38;5;241;43m=\u001b[39;49m\u001b[43mbody\u001b[49m\u001b[43m,\u001b[49m\n\u001b[1;32m    744\u001b[0m \u001b[43m    \u001b[49m\u001b[43mtimeout\u001b[49m\u001b[38;5;241;43m=\u001b[39;49m\u001b[43mtimeout\u001b[49m\u001b[43m,\u001b[49m\n\u001b[1;32m    745\u001b[0m \u001b[43m    \u001b[49m\u001b[43mtoken\u001b[49m\u001b[38;5;241;43m=\u001b[39;49m\u001b[43mtoken\u001b[49m\u001b[43m,\u001b[49m\n\u001b[1;32m    746\u001b[0m \u001b[43m    \u001b[49m\u001b[43mno_retry\u001b[49m\u001b[38;5;241;43m=\u001b[39;49m\u001b[43mno_retry\u001b[49m\u001b[43m,\u001b[49m\n\u001b[1;32m    747\u001b[0m \u001b[43m    \u001b[49m\u001b[43m_include_retry_params\u001b[49m\u001b[38;5;241;43m=\u001b[39;49m\u001b[43m_include_retry_params\u001b[49m\u001b[43m,\u001b[49m\n\u001b[1;32m    748\u001b[0m \u001b[43m    \u001b[49m\u001b[43msocket_timeout\u001b[49m\u001b[38;5;241;43m=\u001b[39;49m\u001b[43msocket_timeout\u001b[49m\u001b[43m,\u001b[49m\n\u001b[1;32m    749\u001b[0m \u001b[43m\u001b[49m\u001b[43m)\u001b[49m\n\u001b[1;32m    750\u001b[0m logger\u001b[38;5;241m.\u001b[39mdebug(\n\u001b[1;32m    751\u001b[0m     \u001b[38;5;124m\"\u001b[39m\u001b[38;5;124mret[code] = \u001b[39m\u001b[38;5;132;01m{code}\u001b[39;00m\u001b[38;5;124m, after post request\u001b[39m\u001b[38;5;124m\"\u001b[39m\u001b[38;5;241m.\u001b[39mformat(\n\u001b[1;32m    752\u001b[0m         code\u001b[38;5;241m=\u001b[39m(ret\u001b[38;5;241m.\u001b[39mget(\u001b[38;5;124m\"\u001b[39m\u001b[38;5;124mcode\u001b[39m\u001b[38;5;124m\"\u001b[39m, \u001b[38;5;124m\"\u001b[39m\u001b[38;5;124mN/A\u001b[39m\u001b[38;5;124m\"\u001b[39m))\n\u001b[1;32m    753\u001b[0m     )\n\u001b[1;32m    754\u001b[0m )\n",
      "File \u001b[0;32m/opt/conda/lib/python3.9/site-packages/snowflake/connector/network.py:854\u001b[0m, in \u001b[0;36mSnowflakeRestful.fetch\u001b[0;34m(self, method, full_url, headers, data, timeout, **kwargs)\u001b[0m\n\u001b[1;32m    853\u001b[0m \u001b[38;5;28;01mwhile\u001b[39;00m \u001b[38;5;28;01mTrue\u001b[39;00m:\n\u001b[0;32m--> 854\u001b[0m     ret \u001b[38;5;241m=\u001b[39m \u001b[38;5;28;43mself\u001b[39;49m\u001b[38;5;241;43m.\u001b[39;49m\u001b[43m_request_exec_wrapper\u001b[49m\u001b[43m(\u001b[49m\n\u001b[1;32m    855\u001b[0m \u001b[43m        \u001b[49m\u001b[43msession\u001b[49m\u001b[43m,\u001b[49m\u001b[43m \u001b[49m\u001b[43mmethod\u001b[49m\u001b[43m,\u001b[49m\u001b[43m \u001b[49m\u001b[43mfull_url\u001b[49m\u001b[43m,\u001b[49m\u001b[43m \u001b[49m\u001b[43mheaders\u001b[49m\u001b[43m,\u001b[49m\u001b[43m \u001b[49m\u001b[43mdata\u001b[49m\u001b[43m,\u001b[49m\u001b[43m \u001b[49m\u001b[43mretry_ctx\u001b[49m\u001b[43m,\u001b[49m\u001b[43m \u001b[49m\u001b[38;5;241;43m*\u001b[39;49m\u001b[38;5;241;43m*\u001b[39;49m\u001b[43mkwargs\u001b[49m\n\u001b[1;32m    856\u001b[0m \u001b[43m    \u001b[49m\u001b[43m)\u001b[49m\n\u001b[1;32m    857\u001b[0m     \u001b[38;5;28;01mif\u001b[39;00m ret \u001b[38;5;129;01mis\u001b[39;00m \u001b[38;5;129;01mnot\u001b[39;00m \u001b[38;5;28;01mNone\u001b[39;00m:\n",
      "File \u001b[0;32m/opt/conda/lib/python3.9/site-packages/snowflake/connector/network.py:971\u001b[0m, in \u001b[0;36mSnowflakeRestful._request_exec_wrapper\u001b[0;34m(self, session, method, full_url, headers, data, retry_ctx, no_retry, token, **kwargs)\u001b[0m\n\u001b[1;32m    970\u001b[0m \u001b[38;5;28;01mif\u001b[39;00m \u001b[38;5;129;01mnot\u001b[39;00m no_retry:\n\u001b[0;32m--> 971\u001b[0m     \u001b[38;5;28;01mraise\u001b[39;00m e\n\u001b[1;32m    972\u001b[0m logger\u001b[38;5;241m.\u001b[39mdebug(\u001b[38;5;124m\"\u001b[39m\u001b[38;5;124mIgnored error\u001b[39m\u001b[38;5;124m\"\u001b[39m, exc_info\u001b[38;5;241m=\u001b[39m\u001b[38;5;28;01mTrue\u001b[39;00m)\n",
      "File \u001b[0;32m/opt/conda/lib/python3.9/site-packages/snowflake/connector/network.py:896\u001b[0m, in \u001b[0;36mSnowflakeRestful._request_exec_wrapper\u001b[0;34m(self, session, method, full_url, headers, data, retry_ctx, no_retry, token, **kwargs)\u001b[0m\n\u001b[1;32m    895\u001b[0m \u001b[38;5;28;01mtry\u001b[39;00m:\n\u001b[0;32m--> 896\u001b[0m     return_object \u001b[38;5;241m=\u001b[39m \u001b[38;5;28;43mself\u001b[39;49m\u001b[38;5;241;43m.\u001b[39;49m\u001b[43m_request_exec\u001b[49m\u001b[43m(\u001b[49m\n\u001b[1;32m    897\u001b[0m \u001b[43m        \u001b[49m\u001b[43msession\u001b[49m\u001b[38;5;241;43m=\u001b[39;49m\u001b[43msession\u001b[49m\u001b[43m,\u001b[49m\n\u001b[1;32m    898\u001b[0m \u001b[43m        \u001b[49m\u001b[43mmethod\u001b[49m\u001b[38;5;241;43m=\u001b[39;49m\u001b[43mmethod\u001b[49m\u001b[43m,\u001b[49m\n\u001b[1;32m    899\u001b[0m \u001b[43m        \u001b[49m\u001b[43mfull_url\u001b[49m\u001b[38;5;241;43m=\u001b[39;49m\u001b[43mfull_url\u001b[49m\u001b[43m,\u001b[49m\n\u001b[1;32m    900\u001b[0m \u001b[43m        \u001b[49m\u001b[43mheaders\u001b[49m\u001b[38;5;241;43m=\u001b[39;49m\u001b[43mheaders\u001b[49m\u001b[43m,\u001b[49m\n\u001b[1;32m    901\u001b[0m \u001b[43m        \u001b[49m\u001b[43mdata\u001b[49m\u001b[38;5;241;43m=\u001b[39;49m\u001b[43mdata\u001b[49m\u001b[43m,\u001b[49m\n\u001b[1;32m    902\u001b[0m \u001b[43m        \u001b[49m\u001b[43mtoken\u001b[49m\u001b[38;5;241;43m=\u001b[39;49m\u001b[43mtoken\u001b[49m\u001b[43m,\u001b[49m\n\u001b[1;32m    903\u001b[0m \u001b[43m        \u001b[49m\u001b[38;5;241;43m*\u001b[39;49m\u001b[38;5;241;43m*\u001b[39;49m\u001b[43mkwargs\u001b[49m\u001b[43m,\u001b[49m\n\u001b[1;32m    904\u001b[0m \u001b[43m    \u001b[49m\u001b[43m)\u001b[49m\n\u001b[1;32m    905\u001b[0m     \u001b[38;5;28;01mif\u001b[39;00m return_object \u001b[38;5;129;01mis\u001b[39;00m \u001b[38;5;129;01mnot\u001b[39;00m \u001b[38;5;28;01mNone\u001b[39;00m:\n",
      "File \u001b[0;32m/opt/conda/lib/python3.9/site-packages/snowflake/connector/network.py:1144\u001b[0m, in \u001b[0;36mSnowflakeRestful._request_exec\u001b[0;34m(self, session, method, full_url, headers, data, token, catch_okta_unauthorized_error, is_raw_text, is_raw_binary, binary_data_handler, socket_timeout, is_okta_authentication)\u001b[0m\n\u001b[1;32m   1139\u001b[0m     logger\u001b[38;5;241m.\u001b[39mdebug(\n\u001b[1;32m   1140\u001b[0m         \u001b[38;5;124m\"\u001b[39m\u001b[38;5;124mHit a timeout error while logging in. Will be handled by \u001b[39m\u001b[38;5;124m\"\u001b[39m\n\u001b[1;32m   1141\u001b[0m         \u001b[38;5;124mf\u001b[39m\u001b[38;5;124m\"\u001b[39m\u001b[38;5;124mauthenticator. Ignore the following. Error stack: \u001b[39m\u001b[38;5;132;01m{\u001b[39;00merr\u001b[38;5;132;01m}\u001b[39;00m\u001b[38;5;124m\"\u001b[39m,\n\u001b[1;32m   1142\u001b[0m         exc_info\u001b[38;5;241m=\u001b[39m\u001b[38;5;28;01mTrue\u001b[39;00m,\n\u001b[1;32m   1143\u001b[0m     )\n\u001b[0;32m-> 1144\u001b[0m     \u001b[38;5;28;01mraise\u001b[39;00m OperationalError(\n\u001b[1;32m   1145\u001b[0m         msg\u001b[38;5;241m=\u001b[39m\u001b[38;5;124m\"\u001b[39m\u001b[38;5;124mConnectionTimeout occurred during login. Will be handled by authenticator\u001b[39m\u001b[38;5;124m\"\u001b[39m,\n\u001b[1;32m   1146\u001b[0m         errno\u001b[38;5;241m=\u001b[39mER_CONNECTION_TIMEOUT,\n\u001b[1;32m   1147\u001b[0m     )\n\u001b[1;32m   1148\u001b[0m \u001b[38;5;28;01melse\u001b[39;00m:\n",
      "\u001b[0;31mOperationalError\u001b[0m: 251011: ConnectionTimeout occurred during login. Will be handled by authenticator",
      "\nThe above exception was the direct cause of the following exception:\n",
      "\u001b[0;31mOperationalError\u001b[0m                          Traceback (most recent call last)",
      "Cell \u001b[0;32mIn[20], line 8\u001b[0m\n\u001b[1;32m      5\u001b[0m     \u001b[38;5;28;01mwith\u001b[39;00m \u001b[38;5;28mopen\u001b[39m(\u001b[38;5;124m'\u001b[39m\u001b[38;5;124m/snowflake/session/token\u001b[39m\u001b[38;5;124m'\u001b[39m, \u001b[38;5;124m'\u001b[39m\u001b[38;5;124mr\u001b[39m\u001b[38;5;124m'\u001b[39m) \u001b[38;5;28;01mas\u001b[39;00m f:\n\u001b[1;32m      6\u001b[0m         \u001b[38;5;28;01mreturn\u001b[39;00m f\u001b[38;5;241m.\u001b[39mread()\n\u001b[0;32m----> 8\u001b[0m conn \u001b[38;5;241m=\u001b[39m \u001b[43msnowflake\u001b[49m\u001b[38;5;241;43m.\u001b[39;49m\u001b[43mconnector\u001b[49m\u001b[38;5;241;43m.\u001b[39;49m\u001b[43mconnect\u001b[49m\u001b[43m(\u001b[49m\n\u001b[1;32m      9\u001b[0m \u001b[43m    \u001b[49m\u001b[43mhost\u001b[49m\u001b[38;5;241;43m=\u001b[39;49m\u001b[38;5;124;43m\"\u001b[39;49m\u001b[38;5;124;43mhttps://fya62509.us-east-1.snowflakecomputing.com\u001b[39;49m\u001b[38;5;124;43m\"\u001b[39;49m\u001b[43m,\u001b[49m\n\u001b[1;32m     10\u001b[0m \u001b[43m    \u001b[49m\u001b[43maccount\u001b[49m\u001b[38;5;241;43m=\u001b[39;49m\u001b[38;5;124;43m\"\u001b[39;49m\u001b[38;5;124;43mRAVIKUMARHALIGODE\u001b[39;49m\u001b[38;5;124;43m\"\u001b[39;49m\u001b[43m,\u001b[49m\n\u001b[1;32m     11\u001b[0m \u001b[43m    \u001b[49m\u001b[43mtoken\u001b[49m\u001b[38;5;241;43m=\u001b[39;49m\u001b[43mget_login_token\u001b[49m\u001b[43m(\u001b[49m\u001b[43m)\u001b[49m\u001b[43m,\u001b[49m\n\u001b[1;32m     12\u001b[0m \u001b[43m    \u001b[49m\u001b[43mauthenticator\u001b[49m\u001b[38;5;241;43m=\u001b[39;49m\u001b[38;5;124;43m\"\u001b[39;49m\u001b[38;5;124;43moauth\u001b[39;49m\u001b[38;5;124;43m\"\u001b[39;49m\u001b[43m,\u001b[49m\n\u001b[1;32m     13\u001b[0m \u001b[43m    \u001b[49m\u001b[43mdatabase\u001b[49m\u001b[38;5;241;43m=\u001b[39;49m\u001b[38;5;124;43m\"\u001b[39;49m\u001b[38;5;124;43mRAVI_TESTING\u001b[39;49m\u001b[38;5;124;43m\"\u001b[39;49m\u001b[43m,\u001b[49m\n\u001b[1;32m     14\u001b[0m \u001b[43m    \u001b[49m\u001b[43mschema\u001b[49m\u001b[38;5;241;43m=\u001b[39;49m\u001b[38;5;124;43m\"\u001b[39;49m\u001b[38;5;124;43mRAVI_TESTING\u001b[39;49m\u001b[38;5;124;43m\"\u001b[39;49m\n\u001b[1;32m     15\u001b[0m \u001b[43m)\u001b[49m\n",
      "File \u001b[0;32m/opt/conda/lib/python3.9/site-packages/snowflake/connector/__init__.py:55\u001b[0m, in \u001b[0;36mConnect\u001b[0;34m(**kwargs)\u001b[0m\n\u001b[1;32m     53\u001b[0m \u001b[38;5;129m@wraps\u001b[39m(SnowflakeConnection\u001b[38;5;241m.\u001b[39m\u001b[38;5;21m__init__\u001b[39m)\n\u001b[1;32m     54\u001b[0m \u001b[38;5;28;01mdef\u001b[39;00m \u001b[38;5;21mConnect\u001b[39m(\u001b[38;5;241m*\u001b[39m\u001b[38;5;241m*\u001b[39mkwargs) \u001b[38;5;241m-\u001b[39m\u001b[38;5;241m>\u001b[39m SnowflakeConnection:\n\u001b[0;32m---> 55\u001b[0m     \u001b[38;5;28;01mreturn\u001b[39;00m \u001b[43mSnowflakeConnection\u001b[49m\u001b[43m(\u001b[49m\u001b[38;5;241;43m*\u001b[39;49m\u001b[38;5;241;43m*\u001b[39;49m\u001b[43mkwargs\u001b[49m\u001b[43m)\u001b[49m\n",
      "File \u001b[0;32m/opt/conda/lib/python3.9/site-packages/snowflake/connector/connection.py:456\u001b[0m, in \u001b[0;36mSnowflakeConnection.__init__\u001b[0;34m(self, connection_name, connections_file_path, **kwargs)\u001b[0m\n\u001b[1;32m    454\u001b[0m     kwargs \u001b[38;5;241m=\u001b[39m _get_default_connection_params()\n\u001b[1;32m    455\u001b[0m \u001b[38;5;28mself\u001b[39m\u001b[38;5;241m.\u001b[39m__set_error_attributes()\n\u001b[0;32m--> 456\u001b[0m \u001b[38;5;28;43mself\u001b[39;49m\u001b[38;5;241;43m.\u001b[39;49m\u001b[43mconnect\u001b[49m\u001b[43m(\u001b[49m\u001b[38;5;241;43m*\u001b[39;49m\u001b[38;5;241;43m*\u001b[39;49m\u001b[43mkwargs\u001b[49m\u001b[43m)\u001b[49m\n\u001b[1;32m    457\u001b[0m \u001b[38;5;28mself\u001b[39m\u001b[38;5;241m.\u001b[39m_telemetry \u001b[38;5;241m=\u001b[39m TelemetryClient(\u001b[38;5;28mself\u001b[39m\u001b[38;5;241m.\u001b[39m_rest)\n\u001b[1;32m    458\u001b[0m \u001b[38;5;28mself\u001b[39m\u001b[38;5;241m.\u001b[39mexpired \u001b[38;5;241m=\u001b[39m \u001b[38;5;28;01mFalse\u001b[39;00m\n",
      "File \u001b[0;32m/opt/conda/lib/python3.9/site-packages/snowflake/connector/connection.py:771\u001b[0m, in \u001b[0;36mSnowflakeConnection.connect\u001b[0;34m(self, **kwargs)\u001b[0m\n\u001b[1;32m    769\u001b[0m             \u001b[38;5;28;01mraise\u001b[39;00m \u001b[38;5;167;01mException\u001b[39;00m(\u001b[38;5;28mstr\u001b[39m(exceptions_dict))\n\u001b[1;32m    770\u001b[0m \u001b[38;5;28;01melse\u001b[39;00m:\n\u001b[0;32m--> 771\u001b[0m     \u001b[38;5;28;43mself\u001b[39;49m\u001b[38;5;241;43m.\u001b[39;49m\u001b[43m__open_connection\u001b[49m\u001b[43m(\u001b[49m\u001b[43m)\u001b[49m\n",
      "File \u001b[0;32m/opt/conda/lib/python3.9/site-packages/snowflake/connector/connection.py:1099\u001b[0m, in \u001b[0;36mSnowflakeConnection.__open_connection\u001b[0;34m(self)\u001b[0m\n\u001b[1;32m   1091\u001b[0m \u001b[38;5;28;01melse\u001b[39;00m:\n\u001b[1;32m   1092\u001b[0m     \u001b[38;5;66;03m# okta URL, e.g., https://<account>.okta.com/\u001b[39;00m\n\u001b[1;32m   1093\u001b[0m     \u001b[38;5;28mself\u001b[39m\u001b[38;5;241m.\u001b[39mauth_class \u001b[38;5;241m=\u001b[39m AuthByOkta(\n\u001b[1;32m   1094\u001b[0m         application\u001b[38;5;241m=\u001b[39m\u001b[38;5;28mself\u001b[39m\u001b[38;5;241m.\u001b[39mapplication,\n\u001b[1;32m   1095\u001b[0m         timeout\u001b[38;5;241m=\u001b[39m\u001b[38;5;28mself\u001b[39m\u001b[38;5;241m.\u001b[39mlogin_timeout,\n\u001b[1;32m   1096\u001b[0m         backoff_generator\u001b[38;5;241m=\u001b[39m\u001b[38;5;28mself\u001b[39m\u001b[38;5;241m.\u001b[39m_backoff_generator,\n\u001b[1;32m   1097\u001b[0m     )\n\u001b[0;32m-> 1099\u001b[0m \u001b[38;5;28;43mself\u001b[39;49m\u001b[38;5;241;43m.\u001b[39;49m\u001b[43mauthenticate_with_retry\u001b[49m\u001b[43m(\u001b[49m\u001b[38;5;28;43mself\u001b[39;49m\u001b[38;5;241;43m.\u001b[39;49m\u001b[43mauth_class\u001b[49m\u001b[43m)\u001b[49m\n\u001b[1;32m   1101\u001b[0m \u001b[38;5;28mself\u001b[39m\u001b[38;5;241m.\u001b[39m_password \u001b[38;5;241m=\u001b[39m \u001b[38;5;28;01mNone\u001b[39;00m  \u001b[38;5;66;03m# ensure password won't persist\u001b[39;00m\n\u001b[1;32m   1102\u001b[0m \u001b[38;5;28mself\u001b[39m\u001b[38;5;241m.\u001b[39mauth_class\u001b[38;5;241m.\u001b[39mreset_secrets()\n",
      "File \u001b[0;32m/opt/conda/lib/python3.9/site-packages/snowflake/connector/connection.py:1386\u001b[0m, in \u001b[0;36mSnowflakeConnection.authenticate_with_retry\u001b[0;34m(self, auth_instance)\u001b[0m\n\u001b[1;32m   1383\u001b[0m \u001b[38;5;28;01mdef\u001b[39;00m \u001b[38;5;21mauthenticate_with_retry\u001b[39m(\u001b[38;5;28mself\u001b[39m, auth_instance) \u001b[38;5;241m-\u001b[39m\u001b[38;5;241m>\u001b[39m \u001b[38;5;28;01mNone\u001b[39;00m:\n\u001b[1;32m   1384\u001b[0m     \u001b[38;5;66;03m# make some changes if needed before real __authenticate\u001b[39;00m\n\u001b[1;32m   1385\u001b[0m     \u001b[38;5;28;01mtry\u001b[39;00m:\n\u001b[0;32m-> 1386\u001b[0m         \u001b[38;5;28;43mself\u001b[39;49m\u001b[38;5;241;43m.\u001b[39;49m\u001b[43m_authenticate\u001b[49m\u001b[43m(\u001b[49m\u001b[43mauth_instance\u001b[49m\u001b[43m)\u001b[49m\n\u001b[1;32m   1387\u001b[0m     \u001b[38;5;28;01mexcept\u001b[39;00m ReauthenticationRequest \u001b[38;5;28;01mas\u001b[39;00m ex:\n\u001b[1;32m   1388\u001b[0m         \u001b[38;5;66;03m# cached id_token expiration error, we have cleaned id_token and try to authenticate again\u001b[39;00m\n\u001b[1;32m   1389\u001b[0m         logger\u001b[38;5;241m.\u001b[39mdebug(\u001b[38;5;124m\"\u001b[39m\u001b[38;5;124mID token expired. Reauthenticating...: \u001b[39m\u001b[38;5;132;01m%s\u001b[39;00m\u001b[38;5;124m\"\u001b[39m, ex)\n",
      "File \u001b[0;32m/opt/conda/lib/python3.9/site-packages/snowflake/connector/connection.py:1458\u001b[0m, in \u001b[0;36mSnowflakeConnection._authenticate\u001b[0;34m(self, auth_instance)\u001b[0m\n\u001b[1;32m   1456\u001b[0m \u001b[38;5;28;01mexcept\u001b[39;00m OperationalError \u001b[38;5;28;01mas\u001b[39;00m auth_op:\n\u001b[1;32m   1457\u001b[0m     \u001b[38;5;28;01mif\u001b[39;00m auth_op\u001b[38;5;241m.\u001b[39merrno \u001b[38;5;241m==\u001b[39m ER_FAILED_TO_CONNECT_TO_DB:\n\u001b[0;32m-> 1458\u001b[0m         \u001b[38;5;28;01mraise\u001b[39;00m auth_op \u001b[38;5;28;01mfrom\u001b[39;00m \u001b[38;5;21;01me\u001b[39;00m\n\u001b[1;32m   1459\u001b[0m     logger\u001b[38;5;241m.\u001b[39mdebug(\u001b[38;5;124m\"\u001b[39m\u001b[38;5;124mContinuing authenticator specific timeout handling\u001b[39m\u001b[38;5;124m\"\u001b[39m)\n\u001b[1;32m   1460\u001b[0m     \u001b[38;5;28;01mcontinue\u001b[39;00m\n",
      "File \u001b[0;32m/opt/conda/lib/python3.9/site-packages/snowflake/connector/connection.py:1435\u001b[0m, in \u001b[0;36mSnowflakeConnection._authenticate\u001b[0;34m(self, auth_instance)\u001b[0m\n\u001b[1;32m   1433\u001b[0m \u001b[38;5;28;01mwhile\u001b[39;00m \u001b[38;5;28;01mTrue\u001b[39;00m:\n\u001b[1;32m   1434\u001b[0m     \u001b[38;5;28;01mtry\u001b[39;00m:\n\u001b[0;32m-> 1435\u001b[0m         \u001b[43mauth_instance\u001b[49m\u001b[38;5;241;43m.\u001b[39;49m\u001b[43mhandle_timeout\u001b[49m\u001b[43m(\u001b[49m\n\u001b[1;32m   1436\u001b[0m \u001b[43m            \u001b[49m\u001b[43mauthenticator\u001b[49m\u001b[38;5;241;43m=\u001b[39;49m\u001b[38;5;28;43mself\u001b[39;49m\u001b[38;5;241;43m.\u001b[39;49m\u001b[43m_authenticator\u001b[49m\u001b[43m,\u001b[49m\n\u001b[1;32m   1437\u001b[0m \u001b[43m            \u001b[49m\u001b[43mservice_name\u001b[49m\u001b[38;5;241;43m=\u001b[39;49m\u001b[38;5;28;43mself\u001b[39;49m\u001b[38;5;241;43m.\u001b[39;49m\u001b[43mservice_name\u001b[49m\u001b[43m,\u001b[49m\n\u001b[1;32m   1438\u001b[0m \u001b[43m            \u001b[49m\u001b[43maccount\u001b[49m\u001b[38;5;241;43m=\u001b[39;49m\u001b[38;5;28;43mself\u001b[39;49m\u001b[38;5;241;43m.\u001b[39;49m\u001b[43maccount\u001b[49m\u001b[43m,\u001b[49m\n\u001b[1;32m   1439\u001b[0m \u001b[43m            \u001b[49m\u001b[43muser\u001b[49m\u001b[38;5;241;43m=\u001b[39;49m\u001b[38;5;28;43mself\u001b[39;49m\u001b[38;5;241;43m.\u001b[39;49m\u001b[43muser\u001b[49m\u001b[43m,\u001b[49m\n\u001b[1;32m   1440\u001b[0m \u001b[43m            \u001b[49m\u001b[43mpassword\u001b[49m\u001b[38;5;241;43m=\u001b[39;49m\u001b[38;5;28;43mself\u001b[39;49m\u001b[38;5;241;43m.\u001b[39;49m\u001b[43m_password\u001b[49m\u001b[43m,\u001b[49m\n\u001b[1;32m   1441\u001b[0m \u001b[43m        \u001b[49m\u001b[43m)\u001b[49m\n\u001b[1;32m   1442\u001b[0m         auth\u001b[38;5;241m.\u001b[39mauthenticate(\n\u001b[1;32m   1443\u001b[0m             auth_instance\u001b[38;5;241m=\u001b[39mauth_instance,\n\u001b[1;32m   1444\u001b[0m             account\u001b[38;5;241m=\u001b[39m\u001b[38;5;28mself\u001b[39m\u001b[38;5;241m.\u001b[39maccount,\n\u001b[0;32m   (...)\u001b[0m\n\u001b[1;32m   1454\u001b[0m             session_parameters\u001b[38;5;241m=\u001b[39m\u001b[38;5;28mself\u001b[39m\u001b[38;5;241m.\u001b[39m_session_parameters,\n\u001b[1;32m   1455\u001b[0m         )\n\u001b[1;32m   1456\u001b[0m     \u001b[38;5;28;01mexcept\u001b[39;00m OperationalError \u001b[38;5;28;01mas\u001b[39;00m auth_op:\n",
      "File \u001b[0;32m/opt/conda/lib/python3.9/site-packages/snowflake/connector/auth/by_plugin.py:212\u001b[0m, in \u001b[0;36mAuthByPlugin.handle_timeout\u001b[0;34m(***failed resolving arguments***)\u001b[0m\n\u001b[1;32m    206\u001b[0m \u001b[38;5;28;01mif\u001b[39;00m \u001b[38;5;129;01mnot\u001b[39;00m \u001b[38;5;28mself\u001b[39m\u001b[38;5;241m.\u001b[39m_retry_ctx\u001b[38;5;241m.\u001b[39mshould_retry:\n\u001b[1;32m    207\u001b[0m     error \u001b[38;5;241m=\u001b[39m OperationalError(\n\u001b[1;32m    208\u001b[0m         msg\u001b[38;5;241m=\u001b[39m\u001b[38;5;124mf\u001b[39m\u001b[38;5;124m\"\u001b[39m\u001b[38;5;124mCould not connect to Snowflake backend after \u001b[39m\u001b[38;5;132;01m{\u001b[39;00m\u001b[38;5;28mself\u001b[39m\u001b[38;5;241m.\u001b[39m_retry_ctx\u001b[38;5;241m.\u001b[39mcurrent_retry_count\u001b[38;5;250m \u001b[39m\u001b[38;5;241m+\u001b[39m\u001b[38;5;250m \u001b[39m\u001b[38;5;241m1\u001b[39m\u001b[38;5;132;01m}\u001b[39;00m\u001b[38;5;124m attempt(s).\u001b[39m\u001b[38;5;124m\"\u001b[39m\n\u001b[1;32m    209\u001b[0m         \u001b[38;5;124m\"\u001b[39m\u001b[38;5;124mAborting\u001b[39m\u001b[38;5;124m\"\u001b[39m,\n\u001b[1;32m    210\u001b[0m         errno\u001b[38;5;241m=\u001b[39mER_FAILED_TO_CONNECT_TO_DB,\n\u001b[1;32m    211\u001b[0m     )\n\u001b[0;32m--> 212\u001b[0m     \u001b[38;5;28;01mraise\u001b[39;00m error\n\u001b[1;32m    213\u001b[0m \u001b[38;5;28;01melse\u001b[39;00m:\n\u001b[1;32m    214\u001b[0m     logger\u001b[38;5;241m.\u001b[39mdebug(\n\u001b[1;32m    215\u001b[0m         \u001b[38;5;124mf\u001b[39m\u001b[38;5;124m\"\u001b[39m\u001b[38;5;124mHit connection timeout, attempt number \u001b[39m\u001b[38;5;132;01m{\u001b[39;00m\u001b[38;5;28mself\u001b[39m\u001b[38;5;241m.\u001b[39m_retry_ctx\u001b[38;5;241m.\u001b[39mcurrent_retry_count\u001b[38;5;250m \u001b[39m\u001b[38;5;241m+\u001b[39m\u001b[38;5;250m \u001b[39m\u001b[38;5;241m1\u001b[39m\u001b[38;5;132;01m}\u001b[39;00m\u001b[38;5;124m.\u001b[39m\u001b[38;5;124m\"\u001b[39m\n\u001b[1;32m    216\u001b[0m         \u001b[38;5;124m\"\u001b[39m\u001b[38;5;124m Will retry in a bit...\u001b[39m\u001b[38;5;124m\"\u001b[39m\n\u001b[1;32m    217\u001b[0m     )\n",
      "\u001b[0;31mOperationalError\u001b[0m: 250001: Could not connect to Snowflake backend after 2 attempt(s).Aborting"
     ]
    }
   ],
   "source": [
    "import os\n",
    "import snowflake.connector\n",
    "\n",
    "def get_login_token():\n",
    "    with open('/snowflake/session/token', 'r') as f:\n",
    "        return f.read()\n",
    "\n",
    "conn = snowflake.connector.connect(\n",
    "    host=\"https://fya62509.us-east-1.snowflakecomputing.com\",\n",
    "    account=\"RAVIKUMARHALIGODE\",\n",
    "    token=get_login_token(),\n",
    "    authenticator=\"oauth\",\n",
    "    database=\"RAVI_TESTING\",\n",
    "    schema=\"RAVI_TESTING\"\n",
    ")"
   ]
  },
  {
   "cell_type": "code",
   "execution_count": null,
   "id": "e6d1eca2-9862-45da-b5c6-eed058758454",
   "metadata": {},
   "outputs": [],
   "source": []
  }
 ],
 "metadata": {
  "kernelspec": {
   "display_name": "Python 3 (ipykernel)",
   "language": "python",
   "name": "python3"
  },
  "language_info": {
   "codemirror_mode": {
    "name": "ipython",
    "version": 3
   },
   "file_extension": ".py",
   "mimetype": "text/x-python",
   "name": "python",
   "nbconvert_exporter": "python",
   "pygments_lexer": "ipython3",
   "version": "3.9.19"
  }
 },
 "nbformat": 4,
 "nbformat_minor": 5
}
